<?xml version="1.0"?>
<robot name="three_wheel_diff_drive" xmlns:xacro="http://www.ros.org/wiki/xacro">

  <xacro:property name="chassis_length" value="0.35"/>
  <xacro:property name="chassis_width"  value="0.25"/>
  <xacro:property name="chassis_height" value="0.08"/>
  <xacro:property name="chassis_mass"   value="2.0"/>
  <xacro:property name="wheel_radius"   value="0.05"/>
  <xacro:property name="wheel_length"   value="0.04"/>
  <xacro:property name="wheel_mass"     value="0.3"/>
  <xacro:property name="lidar_radius"   value="0.05"/>
  <xacro:property name="lidar_height"   value="0.05"/>

  <material name="blue"><color rgba="0.2 0.4 0.8 1.0"/></material>
  <material name="black"><color rgba="0.1 0.1 0.1 1.0"/></material>
  <material name="grey"><color rgba="0.5 0.5 0.5 1.0"/></material>

  <xacro:macro name="cylinder_inertia" params="m r h">
    <inertial>
      <mass value="${m}"/><origin xyz="0 0 0" rpy="0 0 0"/>
      <inertia ixx="${m/12*(3*r*r+h*h)}" ixy="0" ixz="0" iyy="${m/12*(3*r*r+h*h)}" iyz="0" izz="${m/2*r*r}"/>
    </inertial>
  </xacro:macro>

  <xacro:macro name="box_inertia" params="m x y z">
    <inertial>
      <mass value="${m}"/><origin xyz="0 0 0" rpy="0 0 0"/>
      <inertia ixx="${m/12*(y*y+z*z)}" ixy="0" ixz="0" iyy="${m/12*(x*x+z*z)}" iyz="0" izz="${m/12*(x*x+y*y)}"/>
    </inertial>
  </xacro:macro>

  <link name="base_footprint"/>

  <joint name="base_joint" type="fixed">
    <parent link="base_footprint"/><child link="base_link"/>
    <origin xyz="0 0 0.05" rpy="0 0 0"/>
  </joint>

  <link name="base_link">
    <visual>
      <geometry><box size="${chassis_length} ${chassis_width} ${chassis_height}"/></geometry>
      <material name="blue"/>
    </visual>
    <collision>
      <geometry><box size="${chassis_length} ${chassis_width} ${chassis_height}"/></geometry>
    </collision>
    <xacro:box_inertia m="${chassis_mass}" x="${chassis_length}" y="${chassis_width}" z="${chassis_height}"/>
  </link>

  <xacro:macro name="wheel" params="prefix y_reflect">
    <link name="${prefix}_wheel">
      <visual>
        <origin xyz="0 0 0" rpy="${pi/2} 0 0"/>
        <geometry><cylinder radius="${wheel_radius}" length="${wheel_length}"/></geometry>
        <material name="black"/>
      </visual>
      <collision>
        <origin xyz="0 0 0" rpy="${pi/2} 0 0"/>
        <geometry><cylinder radius="${wheel_radius}" length="${wheel_length}"/></geometry>
      </collision>
      <xacro:cylinder_inertia m="${wheel_mass}" r="${wheel_radius}" h="${wheel_length}"/>
    </link>
    <joint name="${prefix}_wheel_joint" type="continuous">
      <parent link="base_link"/><child link="${prefix}_wheel"/>
      <origin xyz="-0.10 ${y_reflect * 0.145} -0.05" rpy="0 0 0"/>
      <axis xyz="0 1 0"/>
    </joint>
  </xacro:macro>

  <xacro:wheel prefix="left" y_reflect="1"/>
  <xacro:wheel prefix="right" y_reflect="-1"/>

  <link name="caster_wheel">
    <visual><geometry><sphere radius="0.025"/></geometry><material name="grey"/></visual>
    <collision><geometry><sphere radius="0.025"/></geometry></collision>
    <inertial><mass value="0.1"/><inertia ixx="0.0001" ixy="0" ixz="0" iyy="0.0001" iyz="0" izz="0.0001"/></inertial>
  </link>
  <joint name="caster_joint" type="fixed">
    <parent link="base_link"/><child link="caster_wheel"/>
    <origin xyz="0.14 0 -0.075" rpy="0 0 0"/>
  </joint>

  <link name="laser_frame">
    <visual>
      <geometry><cylinder radius="${lidar_radius}" length="${lidar_height}"/></geometry>
      <material name="black"/>
    </visual>
    <collision>
      <geometry><cylinder radius="${lidar_radius}" length="${lidar_height}"/></geometry>
    </collision>
    <xacro:cylinder_inertia m="0.1" r="${lidar_radius}" h="${lidar_height}"/>
  </link>

  <joint name="laser_joint" type="fixed">
    <parent link="base_link"/><child link="laser_frame"/>
    <origin xyz="0.1 0 ${chassis_height/2 + lidar_height/2}" rpy="0 0 0"/>
  </joint>

  <gazebo reference="laser_frame">
    <sensor type="ray" name="head_hokuyo_sensor">
      <pose>0 0 0 0 0 0</pose>
      <visualize>true</visualize>
      <update_rate>40</update_rate>
      <ray>
        <scan><horizontal><samples>360</samples><resolution>1</resolution><min_angle>-3.14</min_angle><max_angle>3.14</max_angle></horizontal></scan>
        <range><min>0.10</min><max>12.0</max><resolution>0.01</resolution></range>
      </ray>
      <plugin name="gazebo_ros_head_hokuyo_controller" filename="libgazebo_ros_laser.so">
  <topicName>/three_wheel_diff_drive/scan</topicName> 
  
  <frameName>laser_frame</frameName>
</plugin>
    </sensor>
  </gazebo>

  <gazebo>
    <plugin name="differential_drive_controller" filename="libgazebo_ros_diff_drive.so">
      <leftJoint>left_wheel_joint</leftJoint>
      <rightJoint>right_wheel_joint</rightJoint>
      <wheelSeparation>0.29</wheelSeparation>
      <wheelDiameter>0.1</wheelDiameter>
      <torque>10</torque>
      <commandTopic>cmd_vel</commandTopic>
      <odometryTopic>odom</odometryTopic>
      <odometryFrame>odom</odometryFrame>
      <robotBaseFrame>base_footprint</robotBaseFrame>
      <publishWheelTF>true</publishWheelTF>
      <publishOdomTF>true</publishOdomTF>
    </plugin>
  </gazebo>

</robot>
